<?xml version="1.0"?>

<!-- Brief: Powered robot wheel -->
<!-- Shape, Collision, Inertia: Cylinder with relevant collision and constant inertia -->
<!-- Mounting Location: Center of cylinder -->
<!-- Joint Type: continuous -->
<!-- Param name: the name of the wheel -->
<!-- Param mass: mass of the wheel -->
<!-- Param radius: radius of the wheel -->
<!-- Param width: width of the wheel -->
<!-- Param parent: name of the parent link, defaulted to base_link -->
<!-- Param joint_origin: location of the wheel relative to parent link -->
<robot xmlns:xacro="http://ros.org/wiki/xacro" name="wheel">
    <xacro:macro name="wheel" params="name mass radius width parent:=base_link *joint_origin">
        <!-- Includes -->
        <xacro:include filename="$(find common_description)/urdf/physics/inertia.xacro"/>


        <!-- Wheel link -->
        <link name="${name}_link">
            <xacro:cylinder_inertia mass="${mass}" radius="${radius}" height="${width}">
                <origin xyz="0 0 0" rpy="0 0 0" />
            </xacro:cylinder_inertia>

            <visual>
                <origin xyz="0 0 0" rpy="0 ${pi/2} ${pi/2}" />
                <geometry>
                    <cylinder radius="${radius}" length="${width}" />
                </geometry>
            </visual>

            <collision>
                <origin xyz="0 0 0" rpy="0 ${pi/2} ${pi/2}" />
                <geometry>
                    <cylinder radius="${radius}" length="${width}" />
                </geometry>
            </collision>
        </link>

        <joint name="${name}_joint" type="continuous">
            <xacro:insert_block name="joint_origin" />
            <parent link="${parent}" />
            <child link="${name}_link" />
            <axis xyz="0 1 0" rpy="0 0 0" />
            <limit effort="1000" velocity="1000"/>
            <dynamics damping="0.0001"/>
        </joint>
    </xacro:macro>
</robot>
